=== RUN   TestPassing
--- PASS: TestPassing (0.00s)
=== RUN   TestFailing
    stdlib_test.go:15: This test is designed to fail
--- FAIL: TestFailing (0.00s)
=== RUN   TestDatabaseSuite
    suite_setup_test.go:23: test panicked: failed to connect to `user=user database=testdb`: hostname resolving error: lookup unknown: no such host
        goroutine 22 [running]:
        runtime/debug.Stack()
                /usr/lib/go/src/runtime/debug/stack.go:26 +0x5e
        github.com/stretchr/testify/suite.failOnPanic(0xc000103500, {0xa76e80, 0xc00017ade0})
                /home/raoul/go/pkg/mod/github.com/stretchr/testify@v1.10.0/suite/suite.go:89 +0x37
        github.com/stretchr/testify/suite.recoverAndFailOnPanic(0xc000103500)
                /home/raoul/go/pkg/mod/github.com/stretchr/testify@v1.10.0/suite/suite.go:83 +0x35
        panic({0xa76e80?, 0xc00017ade0?})
                /usr/lib/go/src/runtime/panic.go:792 +0x132
        github.com/raoulmillais/go-test-output.(*DatabaseTestSuite).SetupSuite(0xc000130550)
                /home/raoul/code/go-test-output/suite_setup_test.go:23 +0x6d
        github.com/stretchr/testify/suite.Run(0xc000103500, {0xc0d858, 0xc000130550})
                /home/raoul/go/pkg/mod/github.com/stretchr/testify@v1.10.0/suite/suite.go:157 +0x71c
        github.com/raoulmillais/go-test-output.TestDatabaseSuite(0xc000103500)
                /home/raoul/code/go-test-output/suite_setup_test.go:39 +0x33
        testing.tRunner(0xc000103500, 0xb5b9f8)
                /usr/lib/go/src/testing/testing.go:1792 +0xf4
        created by testing.(*T).Run in goroutine 1
                /usr/lib/go/src/testing/testing.go:1851 +0x413
--- FAIL: TestDatabaseSuite (3.49s)
=== RUN   TestSimpleSuite
=== RUN   TestSimpleSuite/TestFailing
    suite_test.go:24:
                Error Trace:    /home/raoul/code/go-test-output/suite_test.go:24
                Error:          Should be true
                Test:           TestSimpleSuite/TestFailing
                Messages:       This should fail
=== RUN   TestSimpleSuite/TestPanics
    suite_test.go:28: test panicked: something terrible happened in the test function in a test suite
        goroutine 25 [running]:
        runtime/debug.Stack()
                /usr/lib/go/src/runtime/debug/stack.go:26 +0x5e
        github.com/stretchr/testify/suite.failOnPanic(0xc0003761c0, {0xa3f1a0, 0xc04460})
                /home/raoul/go/pkg/mod/github.com/stretchr/testify@v1.10.0/suite/suite.go:89 +0x37
        github.com/stretchr/testify/suite.Run.func1.1()
                /home/raoul/go/pkg/mod/github.com/stretchr/testify@v1.10.0/suite/suite.go:188 +0x299
        panic({0xa3f1a0?, 0xc04460?})
                /usr/lib/go/src/runtime/panic.go:792 +0x132
        github.com/raoulmillais/go-test-output.(*SimpleTestSuite).TestPanics(0x0?)
                /home/raoul/code/go-test-output/suite_test.go:28 +0x25
        reflect.Value.call({0xc000281300?, 0xc00011fd98?, 0x13?}, {0xb2de64, 0x4}, {0xc000099f28, 0x1, 0x1?})
                /usr/lib/go/src/reflect/value.go:584 +0xca6
        reflect.Value.Call({0xc000281300?, 0xc00011fd98?, 0xf28748?}, {0xc000084f28?, 0xf?, 0x0?})
                /usr/lib/go/src/reflect/value.go:368 +0xb9
        github.com/stretchr/testify/suite.Run.func1(0xc0003761c0)
                /home/raoul/go/pkg/mod/github.com/stretchr/testify@v1.10.0/suite/suite.go:202 +0x476
        testing.tRunner(0xc0003761c0, 0xc0001a8510)
                /usr/lib/go/src/testing/testing.go:1792 +0xf4
        created by testing.(*T).Run in goroutine 23
                /usr/lib/go/src/testing/testing.go:1851 +0x413
=== RUN   TestSimpleSuite/TestPassing
=== RUN   TestSimpleSuite/TestSkipped
    suite_test.go:19: Skipping this test
--- FAIL: TestSimpleSuite (0.00s)
    --- FAIL: TestSimpleSuite/TestFailing (0.00s)
    --- FAIL: TestSimpleSuite/TestPanics (0.00s)
    --- PASS: TestSimpleSuite/TestPassing (0.00s)
    --- SKIP: TestSimpleSuite/TestSkipped (0.00s)
FAIL
FAIL    github.com/raoulmillais/go-test-output  3.492s
FAIL
